<!-- Cheetah Model

    The state space is populated with joints in the order that they are
    defined in this file. The actuators also operate on joints.

    State-Space (name/joint/parameter):
        - rootx     slider      position (m)
        - rootz     slider      position (m)
        - rooty     hinge       angle (rad)
        - bthigh    hinge       angle (rad)
        - bshin     hinge       angle (rad)
        - bfoot     hinge       angle (rad)
        - fthigh    hinge       angle (rad)
        - fshin     hinge       angle (rad)
        - ffoot     hinge       angle (rad)
        - rootx     slider      velocity (m/s)
        - rootz     slider      velocity (m/s)
        - rooty     hinge       angular velocity (rad/s)
        - bthigh    hinge       angular velocity (rad/s)
        - bshin     hinge       angular velocity (rad/s)
        - bfoot     hinge       angular velocity (rad/s)
        - fthigh    hinge       angular velocity (rad/s)
        - fshin     hinge       angular velocity (rad/s)
        - ffoot     hinge       angular velocity (rad/s)

    Actuators (name/actuator/parameter):
        - bthigh    hinge       torque (N m)
        - bshin     hinge       torque (N m)
        - bfoot     hinge       torque (N m)
        - fthigh    hinge       torque (N m)
        - fshin     hinge       torque (N m)
        - ffoot     hinge       torque (N m)

-->

<mujoco model="cheetah">
  <!-- defaults -->
  <compiler angle="radian" coordinate="local" inertiafromgeom="true"/>
  <default>
    <!-- in this model, mass is calculated based on density -->
    <joint armature=".1" damping=".01" limited="true" solimplimit="0 .8 .03" solreflimit=".02 1" stiffness="8"/>
    <geom conaffinity="0" condim="3" contype="1" friction="1 .1 .1" rgba="0.8 0.6 .4 1" solimp="0.0 0.8 0.01" solref="0.02 1"/>
    <motor ctrllimited="true" ctrlrange="-1 1"/>
  </default>
  <size nstack="300000" nuser_geom="1"/>
  <option gravity="0 0 -9.81" timestep="0.01"/>
  <!-- sky and floor -->
  <asset>
    <texture builtin="gradient" height="100" rgb1="1 1 1" rgb2="0 0 0" type="skybox" width="100"/>
    <texture builtin="flat" height="1278" mark="cross" markrgb="1 1 1" name="texgeom" random="0.01" rgb1="0.8 0.6 0.4" rgb2="0.8 0.6 0.4" type="cube" width="127"/>
    <texture builtin="checker" height="100" name="texplane" rgb1="0 0 0" rgb2="0.8 0.8 0.8" type="2d" width="100"/>
    <material name="MatPlane" reflectance="0.5" shininess="1" specular="1" texrepeat="60 60" texture="texplane"/>
    <material name="geom" texture="texgeom" texuniform="true"/>
  </asset>
  <worldbody>
    <light cutoff="100" diffuse="1 1 1" dir="-0 0 -1.3" directional="true" exponent="1" pos="0 0 1.3" specular=".1 .1 .1"/>
    <geom conaffinity="1" condim="3" material="MatPlane" name="floor" pos="0 0 0" rgba="0.8 0.9 0.8 1" size="40 40 40" type="plane"/>
    <!-- body -->
    <!-- torso -->
    <body name="torso" pos="0 0 .7">
      <camera name="track" mode="trackcom" pos="0 -3 0.3" xyaxes="1 0 0 0 0 1"/>
      <joint armature="0" axis="1 0 0" damping="0" limited="false" name="rootx" pos="0 0 0" stiffness="0" type="slide"/>
      <joint armature="0" axis="0 0 1" damping="0" limited="false" name="rootz" pos="0 0 0" stiffness="0" type="slide"/>
      <joint armature="0" axis="0 1 0" damping="0" limited="false" name="rooty" pos="0 0 0" stiffness="0" type="hinge"/>
      <geom name="torso" size=".4 .25 .05" type="box"/>
      <geom axisangle="0 1 0 .87" density="10" name="neck" pos=".4 0 .075" size="0.046 .075" type="capsule"/>
      <geom axisangle="0 1 0 1.7" density="10" name="head" pos=".5 0 .18" size="0.08 .095 0.2" type="ellipsoid"/>
      <geom axisangle="0 1 0 -.87" density="10" name="tail" pos="-.43 0 .075" size="0.026 .035" type="capsule"/>
      <!-- <site name='tip'  pos='.15 0 .11'/>-->

      <!-- right -->
      <!-- torso/rbthigh -->
      <body name="rbthigh" pos="-.35 0 0">
        <joint axis="0 1 0" damping="4.5" name="rbthigh" pos="0 0 0" range="-1 .7" stiffness="180" type="hinge"/>
        <geom axisangle="0 1 0 .52" name="rbthigh" pos="-.07 -.25 -.12" size="0.046 .133" type="capsule"/>
        <!-- torso/rbthigh/rbshin -->
        <body name="rbshin" pos="-.14 0 -.24">
          <joint axis="0 1 0" damping="3" name="rbshin" pos="0 0 0" range="-1.2 .87" stiffness="120" type="hinge"/>
          <geom axisangle="0 1 0 -.6" name="rbshin" pos=".065 -.25 -.09" rgba="0.9 0.6 0.6 1" size="0.046 .106" type="capsule"/>
          <site axisangle="0 1 0 -.6" name="rb_sensor_site" pos=".12 -.25 -.17" rgba="0 1 0 .1" size="0.05 .010" type="capsule"/>
        </body>
      </body>
      <!-- torso/rfthigh -->
      <body name="rfthigh" pos=".35 0 0">
        <joint axis="0 1 0" damping="4.5" name="rfthigh" pos="0 0 0" range="-1 .7" stiffness="180" type="hinge"/>
        <geom axisangle="0 1 0 .52" name="rfthigh" pos="-.07 -.25 -.12" size="0.046 .133" type="capsule"/>
        <!-- torso/rfthigh/rfshin -->
        <body name="rfshin" pos="-.14 0 -.24">
          <joint axis="0 1 0" damping="3" name="rfshin" pos="0 0 0" range="-1.2 .87" stiffness="120" type="hinge"/>
          <geom axisangle="0 1 0 -.6" name="rfshin" pos=".065 -.25 -.09" rgba="0.9 0.6 0.6 1" size="0.046 .106" type="capsule"/>
          <site axisangle="0 1 0 -.6" name="rf_sensor_site" pos=".12 -.25 -.17" rgba="0 1 0 .1" size="0.05 .010" type="capsule"/>
        </body>
      </body>

      <!-- left -->
      <!-- torso/lbthigh -->
      <body name="lbthigh" pos="-.35 0 0">
        <joint axis="0 1 0" damping="4.5" name="lbthigh" pos="0 0 0" range="-1 .7" stiffness="180" type="hinge"/>
        <geom axisangle="0 1 0 .52" name="lbthigh" pos="-.07 .25 -.12" size="0.046 .133" type="capsule"/>
        <!-- torso/lbthigh/lbshin -->
        <body name="lbshin" pos="-.14 0 -.24">
          <joint axis="0 1 0" damping="3" name="lbshin" pos="0 0 0" range="-1.2 .87" stiffness="120" type="hinge"/>
          <geom axisangle="0 1 0 -.6" name="lbshin" pos=".065 .25 -.09" rgba="0.9 0.6 0.6 1" size="0.046 .106" type="capsule"/>
          <site axisangle="0 1 0 -.6" name="lb_sensor_site" pos=".12 .25 -.17" rgba="0 1 0 .1" size="0.05 .010" type="capsule"/>
        </body>
      </body>
      <!-- torso/lfthigh -->
      <body name="lfthigh" pos=".35 0 0">
        <joint axis="0 1 0" damping="4.5" name="lfthigh" pos="0 0 0" range="-1 .7" stiffness="180" type="hinge"/>
        <geom axisangle="0 1 0 .52" name="lfthigh" pos="-.07 .25 -.12" size="0.046 .133" type="capsule"/>
        <!-- torso/lfthigh/lfshin -->
        <body name="lfshin" pos="-.14 0 -.24">
          <joint axis="0 1 0" damping="3" name="lfshin" pos="0 0 0" range="-1.2 .87" stiffness="120" type="hinge"/>
          <geom axisangle="0 1 0 -.6" name="lfshin" pos=".065 .25 -.09" rgba="0.9 0.6 0.6 1" size="0.046 .106" type="capsule"/>
          <site axisangle="0 1 0 -.6" name="lf_sensor_site" pos=".12 .25 -.17" rgba="0 1 0 .1" size="0.05 .010" type="capsule"/>
        </body>
      </body>
    </body>
  </worldbody>
  <actuator>
    <motor gear="120" joint="rbthigh" name="rbthigh"/>
    <motor gear="90" joint="rbshin" name="rbshin"/>
    <motor gear="120" joint="rfthigh" name="rfthigh"/>
    <motor gear="60" joint="rfshin" name="rfshin"/>
    <motor gear="120" joint="lbthigh" name="lbthigh"/>
    <motor gear="90" joint="lbshin" name="lbshin"/>
    <motor gear="120" joint="lfthigh" name="lfthigh"/>
    <motor gear="60" joint="lfshin" name="lfshin"/>
  </actuator>

  <sensor>
     <touch name="rb_sensor" site="rb_sensor_site" />
     <touch name="rf_sensor" site="rf_sensor_site" />
     <touch name="lb_sensor" site="lb_sensor_site" />
     <touch name="lf_sensor" site="lf_sensor_site" />
  </sensor>
</mujoco>
